<?xml version="1.0" encoding="UTF-8" standalone="yes" ?>
<!DOCTYPE bugzilla SYSTEM "https://bugzilla.redhat.com/page.cgi?id=bugzilla.dtd">

<bugzilla version="4.4.12068.1"
          urlbase="https://bugzilla.redhat.com/"
          
          maintainer="bugzilla-error-list@redhat.com"
>

    <bug>
          <bug_id>1307063</bug_id>
          
          <creation_ts>2016-02-12 10:40:00 -0500</creation_ts>
          <short_desc>TypeError: nothing connected to &lt;bound method NetworkControlBox.on_device_added...</short_desc>
          <delta_ts>2017-03-01 10:50:47 -0500</delta_ts>
          <reporter_accessible>1</reporter_accessible>
          <cclist_accessible>1</cclist_accessible>
          <classification_id>2</classification_id>
          <classification>Fedora</classification>
          <product>Fedora</product>
          <component>anaconda</component>
          <version>24</version>
          <rep_platform>Unspecified</rep_platform>
          <op_sys>Unspecified</op_sys>
          <bug_status>CLOSED</bug_status>
          <resolution>RAWHIDE</resolution>
          
          
          <bug_file_loc></bug_file_loc>
          <status_whiteboard></status_whiteboard>
          <keywords></keywords>
          <priority>unspecified</priority>
          <bug_severity>unspecified</bug_severity>
          <target_milestone>---</target_milestone>
          
          
          <everconfirmed>1</everconfirmed>
          <reporter name="Chris Lumens">clumens</reporter>
          <assigned_to name="Anaconda Maintenance Team">anaconda-maint-list</assigned_to>
          <cc>anaconda-maint-list</cc>
    
    
    <cc>g.kaviyarasu</cc>
    
    
    <cc>jonathan</cc>
    
    
    <cc>vanmeeuwen+fedora</cc>
          <qa_contact name="Fedora Extras Quality Assurance">extras-qa</qa_contact>
          
          <cf_fixed_in>anaconda-24.13-1</cf_fixed_in>
          <cf_doc_type>Bug Fix</cf_doc_type>
          <cf_release_notes></cf_release_notes>
          <cf_story_points>---</cf_story_points>
          
          <cf_environment></cf_environment>
          <cf_last_closed>2017-03-01 10:50:47</cf_last_closed>
          <cf_type>Bug</cf_type>
          <cf_regression_status>---</cf_regression_status>
          <cf_mount_type>---</cf_mount_type>
          <cf_documentation_action>---</cf_documentation_action>
          <cf_crm></cf_crm>
          <cf_verified_branch></cf_verified_branch>
          <cf_category>---</cf_category>
          <cf_ovirt_team>---</cf_ovirt_team>
          
          <cf_cloudforms_team>---</cf_cloudforms_team>
          
          
          
          
          <target_release>---</target_release>
          
          <votes>0</votes>

      

      

      

          <comment_sort_order>oldest_to_newest</comment_sort_order>  
          <long_desc isprivate="0" >
    <commentid>9056331</commentid>
    <comment_count>0</comment_count>
    <who name="Chris Lumens">clumens</who>
    <bug_when>2016-02-12 10:40:08 -0500</bug_when>
    <thetext>Found by the groups-and-envs-2 test:

Traceback (most recent call last):
File &quot;/usr/lib64/python3.5/site-packages/pyanaconda/ui/gui/hubs/summary.py&quot;, line 74, in _on_continue_clicked
    spoke.finished()
File &quot;/usr/lib64/python3.5/site-packages/pyanaconda/ui/gui/spokes/network.py&quot;, line 1504, in finished
    self.network_control_box.disconnect_client_callbacks()
File &quot;/usr/lib64/python3.5/site-packages/pyanaconda/ui/gui/spokes/network.py&quot;, line 1167, in disconnect_client_callbacks
    self.client.disconnect_by_func(self.on_device_added)

TypeError: nothing connected to &lt;bound method NetworkControlBox.on_device_added of &lt;network.NetworkControlBox object at 0x7f6dc3634900 (pyanaconda+ui+gui+spokes+network+NetworkControlBox at 0x560f705f2d80)&gt;&gt;

Full logs are available here:  http://jenkins.install.bos.redhat.com/job/kickstart_tests/462/artifact/kstest-groups-and-envs-2.wQffdZ0i/virt-install.log</thetext>
  </long_desc><long_desc isprivate="0" >
    <commentid>9093154</commentid>
    <comment_count>1</comment_count>
    <who name="Jan Kurik">jkurik</who>
    <bug_when>2016-02-24 09:30:54 -0500</bug_when>
    <thetext>This bug appears to have been reported against &apos;rawhide&apos; during the Fedora 24 development cycle.
Changing version to &apos;24&apos;.

More information and reason for this action is here:
https://fedoraproject.org/wiki/Fedora_Program_Management/HouseKeeping/Fedora24#Rawhide_Rebase</thetext>
  </long_desc>
      
      

    </bug>

</bugzilla>