<?xml version="1.0" encoding="UTF-8" standalone="yes" ?>
<!DOCTYPE bugzilla SYSTEM "https://bugzilla.redhat.com/page.cgi?id=bugzilla.dtd">

<bugzilla version="4.4.12068.1"
          urlbase="https://bugzilla.redhat.com/"
          
          maintainer="bugzilla-error-list@redhat.com"
>

    <bug>
          <bug_id>1331001</bug_id>
          
          <creation_ts>2016-04-27 08:30:00 -0400</creation_ts>
          <short_desc>Hostname with IPv6 address returning status code 400 BAD request</short_desc>
          <delta_ts>2016-05-16 18:25:32 -0400</delta_ts>
          <reporter_accessible>1</reporter_accessible>
          <cclist_accessible>1</cclist_accessible>
          <classification_id>2</classification_id>
          <classification>Fedora</classification>
          <product>Fedora</product>
          <component>python-urllib3</component>
          <version>24</version>
          <rep_platform>x86_64</rep_platform>
          <op_sys>Linux</op_sys>
          <bug_status>CLOSED</bug_status>
          <resolution>ERRATA</resolution>
          
          
          <bug_file_loc></bug_file_loc>
          <status_whiteboard></status_whiteboard>
          <keywords></keywords>
          <priority>unspecified</priority>
          <bug_severity>high</bug_severity>
          <target_milestone>---</target_milestone>
          
          
          <everconfirmed>1</everconfirmed>
          <reporter name="Jiri Konecny">jkonecny</reporter>
          <assigned_to name="Fedora Infrastructure SIG">infra-sig</assigned_to>
          <cc>infra-sig</cc>
    
    
    <cc>rbean</cc>
    
    
    <cc>sagarun</cc>
          <qa_contact name="Fedora Extras Quality Assurance">extras-qa</qa_contact>
          
          <cf_fixed_in>python-urllib3-1.15.1-1.fc23 python-urllib3-1.15.1-1.fc24 python-urllib3-1.15.1-1.fc22</cf_fixed_in>
          <cf_doc_type>Bug Fix</cf_doc_type>
          <cf_release_notes></cf_release_notes>
          <cf_story_points>---</cf_story_points>
          
          <cf_environment></cf_environment>
          <cf_last_closed>2016-05-06 15:24:06</cf_last_closed>
          <cf_type>Bug</cf_type>
          <cf_regression_status>---</cf_regression_status>
          <cf_mount_type>---</cf_mount_type>
          <cf_documentation_action>---</cf_documentation_action>
          <cf_crm></cf_crm>
          <cf_verified_branch></cf_verified_branch>
          <cf_category>---</cf_category>
          <cf_ovirt_team>---</cf_ovirt_team>
          
          <cf_cloudforms_team>---</cf_cloudforms_team>
          
          
          
          
          <target_release>---</target_release>
          
          <votes>0</votes>

      

      

      

          <comment_sort_order>oldest_to_newest</comment_sort_order>  
          <long_desc isprivate="0" >
    <commentid>9273047</commentid>
    <comment_count>0</comment_count>
      <attachid>1151358</attachid>
    <who name="Jiri Konecny">jkonecny</who>
    <bug_when>2016-04-27 08:30:17 -0400</bug_when>
    <thetext>Created attachment 1151358
reproducer.py

Description of problem:
HTTP request GET on hostname in format http://[2620:0::1]/rawhide/.treeinfo is failing with return code 400 BAD REQUEST. WGET and CURL working without problems.
It&apos;s working properly with IPv4 too.

As a side effect this is also breaking python-requests package.


Version-Release number of selected component (if applicable):
python3-urllib3-1.13.1-3

How reproducible:
Always

Steps to Reproduce:
You can use my small reproducer.

Actual results:
Returning 400 BAD REQUEST.

Expected results:
We should get data from a server.

Additional info:
I&apos;m attaching the minimal reproducer.</thetext>
  </long_desc><long_desc isprivate="0" >
    <commentid>9289316</commentid>
    <comment_count>1</comment_count>
    <who name="Fedora Update System">updates</who>
    <bug_when>2016-05-03 13:41:39 -0400</bug_when>
    <thetext>python-pysocks-1.5.6-2.fc24 python-requests-2.10.0-1.fc24 python-urllib3-1.15.1-1.fc24 has been submitted as an update to Fedora 24. https://bodhi.fedoraproject.org/updates/FEDORA-2016-5fd6be4390</thetext>
  </long_desc><long_desc isprivate="0" >
    <commentid>9289322</commentid>
    <comment_count>2</comment_count>
    <who name="Fedora Update System">updates</who>
    <bug_when>2016-05-03 13:42:23 -0400</bug_when>
    <thetext>python-pysocks-1.5.6-2.fc23 python-requests-2.10.0-1.fc23 python-urllib3-1.15.1-1.fc23 has been submitted as an update to Fedora 23. https://bodhi.fedoraproject.org/updates/FEDORA-2016-b9b61b26d3</thetext>
  </long_desc><long_desc isprivate="0" >
    <commentid>9289337</commentid>
    <comment_count>3</comment_count>
    <who name="Fedora Update System">updates</who>
    <bug_when>2016-05-03 13:43:27 -0400</bug_when>
    <thetext>python-pysocks-1.5.6-2.fc22 python-requests-2.10.0-1.fc22 python-urllib3-1.15.1-1.fc22 has been submitted as an update to Fedora 22. https://bodhi.fedoraproject.org/updates/FEDORA-2016-a5e7a7d75b</thetext>
  </long_desc><long_desc isprivate="0" >
    <commentid>9290534</commentid>
    <comment_count>4</comment_count>
    <who name="Fedora Update System">updates</who>
    <bug_when>2016-05-04 02:53:07 -0400</bug_when>
    <thetext>python-pysocks-1.5.6-2.fc22, python-requests-2.10.0-1.fc22, python-urllib3-1.15.1-1.fc22 has been pushed to the Fedora 22 testing repository. If problems still persist, please make note of it in this bug report.
See https://fedoraproject.org/wiki/QA:Updates_Testing for
instructions on how to install test updates.
You can provide feedback for this update here: https://bodhi.fedoraproject.org/updates/FEDORA-2016-a5e7a7d75b</thetext>
  </long_desc><long_desc isprivate="0" >
    <commentid>9290649</commentid>
    <comment_count>5</comment_count>
    <who name="Fedora Update System">updates</who>
    <bug_when>2016-05-04 03:25:27 -0400</bug_when>
    <thetext>python-pysocks-1.5.6-2.fc23, python-requests-2.10.0-1.fc23, python-urllib3-1.15.1-1.fc23 has been pushed to the Fedora 23 testing repository. If problems still persist, please make note of it in this bug report.
See https://fedoraproject.org/wiki/QA:Updates_Testing for
instructions on how to install test updates.
You can provide feedback for this update here: https://bodhi.fedoraproject.org/updates/FEDORA-2016-b9b61b26d3</thetext>
  </long_desc><long_desc isprivate="0" >
    <commentid>9292222</commentid>
    <comment_count>6</comment_count>
    <who name="Fedora Update System">updates</who>
    <bug_when>2016-05-04 10:30:00 -0400</bug_when>
    <thetext>python-pysocks-1.5.6-2.fc24, python-requests-2.10.0-1.fc24, python-urllib3-1.15.1-1.fc24 has been pushed to the Fedora 24 testing repository. If problems still persist, please make note of it in this bug report.
See https://fedoraproject.org/wiki/QA:Updates_Testing for
instructions on how to install test updates.
You can provide feedback for this update here: https://bodhi.fedoraproject.org/updates/FEDORA-2016-5fd6be4390</thetext>
  </long_desc><long_desc isprivate="0" >
    <commentid>9300381</commentid>
    <comment_count>7</comment_count>
    <who name="Fedora Update System">updates</who>
    <bug_when>2016-05-06 15:23:51 -0400</bug_when>
    <thetext>python-pysocks-1.5.6-2.fc23, python-requests-2.10.0-1.fc23, python-urllib3-1.15.1-1.fc23 has been pushed to the Fedora 23 stable repository. If problems still persist, please make note of it in this bug report.</thetext>
  </long_desc><long_desc isprivate="0" >
    <commentid>9301195</commentid>
    <comment_count>8</comment_count>
    <who name="Fedora Update System">updates</who>
    <bug_when>2016-05-07 07:39:17 -0400</bug_when>
    <thetext>python-pysocks-1.5.6-2.fc24, python-requests-2.10.0-1.fc24, python-urllib3-1.15.1-1.fc24 has been pushed to the Fedora 24 stable repository. If problems still persist, please make note of it in this bug report.</thetext>
  </long_desc><long_desc isprivate="0" >
    <commentid>9331305</commentid>
    <comment_count>9</comment_count>
    <who name="Fedora Update System">updates</who>
    <bug_when>2016-05-16 18:25:22 -0400</bug_when>
    <thetext>python-pysocks-1.5.6-2.fc22, python-requests-2.10.0-1.fc22, python-urllib3-1.15.1-1.fc22 has been pushed to the Fedora 22 stable repository. If problems still persist, please make note of it in this bug report.</thetext>
  </long_desc>
      
          <attachment
              isobsolete="0"
              ispatch="0"
              isprivate="0"
          >
            <attachid>1151358</attachid>
            <date>2016-04-27 08:30:00 -0400</date>
            <delta_ts>2016-04-27 08:30:17 -0400</delta_ts>
            <desc>reproducer.py</desc>
            <filename>urllib3-ipv6-repro.py</filename>
            <type>text/x-python</type>
            <size>156</size>
            <attacher name="Jiri Konecny">jkonecny</attacher>
            
              <data encoding="base64">IyEvdXNyL2Jpbi9weXRob24zCgppbXBvcnQgdXJsbGliMwoKaHR0cCA9IHVybGxpYjMuUG9vbE1h
bmFnZXIoKQpyID0gaHR0cC5yZXF1ZXN0KCJHRVQiLCAiaHR0cDovL1syNjIwOjA6MDoxOjoxXS90
cmVlcy9yYXdoaWRlLy50cmVlaW5mbyIpCgpwcmludChyLnN0YXR1cykK
</data>

          </attachment>
      

    </bug>

</bugzilla>