<?xml version="1.0" encoding="UTF-8" standalone="yes" ?>
<!DOCTYPE bugzilla SYSTEM "https://bugzilla.redhat.com/page.cgi?id=bugzilla.dtd">

<bugzilla version="4.4.12068.1"
          urlbase="https://bugzilla.redhat.com/"
          
          maintainer="bugzilla-error-list@redhat.com"
>

    <bug>
          <bug_id>1351935</bug_id>
          
          <creation_ts>2016-07-01 04:13:00 -0400</creation_ts>
          <short_desc>python3.5 ImportError on subprocess.mswindows</short_desc>
          <delta_ts>2016-07-05 00:54:31 -0400</delta_ts>
          <reporter_accessible>1</reporter_accessible>
          <cclist_accessible>1</cclist_accessible>
          <classification_id>2</classification_id>
          <classification>Fedora</classification>
          <product>Fedora</product>
          <component>python-invoke</component>
          <version>24</version>
          <rep_platform>Unspecified</rep_platform>
          <op_sys>Unspecified</op_sys>
          <bug_status>CLOSED</bug_status>
          <resolution>ERRATA</resolution>
          
          
          <bug_file_loc></bug_file_loc>
          <status_whiteboard></status_whiteboard>
          <keywords></keywords>
          <priority>unspecified</priority>
          <bug_severity>unspecified</bug_severity>
          <target_milestone>---</target_milestone>
          
          
          <everconfirmed>1</everconfirmed>
          <reporter name="Emanuele Di Giacomo">emanuele.digiacomo</reporter>
          <assigned_to name="Athmane Madjoudj">athmanem</assigned_to>
          <cc>athmanem</cc>
          <qa_contact name="Fedora Extras Quality Assurance">extras-qa</qa_contact>
          
          <cf_fixed_in>python-invoke-0.13.0-2.fc24</cf_fixed_in>
          <cf_doc_type>If docs needed, set a value</cf_doc_type>
          <cf_release_notes></cf_release_notes>
          <cf_story_points>---</cf_story_points>
          
          <cf_environment></cf_environment>
          <cf_last_closed>2016-07-05 00:54:31</cf_last_closed>
          <cf_type>Bug</cf_type>
          <cf_regression_status>---</cf_regression_status>
          <cf_mount_type>---</cf_mount_type>
          <cf_documentation_action>---</cf_documentation_action>
          <cf_crm></cf_crm>
          <cf_verified_branch></cf_verified_branch>
          <cf_category>---</cf_category>
          <cf_ovirt_team>---</cf_ovirt_team>
          
          <cf_cloudforms_team>---</cf_cloudforms_team>
          
          
          
          
          <target_release>---</target_release>
          
          <votes>0</votes>

      

      

      

          <comment_sort_order>oldest_to_newest</comment_sort_order>  
          <long_desc isprivate="0" >
    <commentid>9471417</commentid>
    <comment_count>0</comment_count>
      <attachid>1174837</attachid>
    <who name="Emanuele Di Giacomo">emanuele.digiacomo</who>
    <bug_when>2016-07-01 04:13:00 -0400</bug_when>
    <thetext>Created attachment 1174837
Patch for invoke/monkey.py

Description of problem:
An ImportError exception is thrown when importing the module under python3.5.

Version-Release number of selected component (if applicable):
0.9.0-7.fc24

How reproducible:
always

Steps to Reproduce:
1. dnf install python3-invoke
2. python3 -c &quot;import invoke&quot;

Actual results:

Traceback (most recent call last):
  File &quot;&lt;string&gt;&quot;, line 1, in &lt;module&gt;
  File &quot;/usr/lib/python3.5/site-packages/invoke/__init__.py&quot;, line 2, in &lt;module&gt;
    from .tasks import task, ctask, Task
  File &quot;/usr/lib/python3.5/site-packages/invoke/tasks.py&quot;, line 11, in &lt;module&gt;
    from .context import Context
  File &quot;/usr/lib/python3.5/site-packages/invoke/context.py&quot;, line 3, in &lt;module&gt;
    from .runner import run
  File &quot;/usr/lib/python3.5/site-packages/invoke/runner.py&quot;, line 5, in &lt;module&gt;
    from .monkey import Popen, PIPE
  File &quot;/usr/lib/python3.5/site-packages/invoke/monkey.py&quot;, line 4, in &lt;module&gt;
    from subprocess import Popen as OriginalPopen, mswindows, PIPE
ImportError: cannot import name &apos;mswindows&apos;

Expected results:

module successfully loaded.

Additional info:
Starting from python3.5, the submodule subprocess.mswindows was renamed subprocess._mswindows. A patch is provided as attachment.</thetext>
  </long_desc><long_desc isprivate="0" >
    <commentid>9473348</commentid>
    <comment_count>1</comment_count>
    <who name="Athmane Madjoudj">athmanem</who>
    <bug_when>2016-07-01 17:12:46 -0400</bug_when>
    <thetext>I&apos;m going to rebase to 0.13.0 (already in rawhide).</thetext>
  </long_desc><long_desc isprivate="0" >
    <commentid>9473476</commentid>
    <comment_count>2</comment_count>
    <who name="Fedora Update System">updates</who>
    <bug_when>2016-07-01 18:40:00 -0400</bug_when>
    <thetext>python-invoke-0.13.0-2.fc24 has been submitted as an update to Fedora 24. https://bodhi.fedoraproject.org/updates/FEDORA-2016-5bf9314019</thetext>
  </long_desc><long_desc isprivate="0" >
    <commentid>9474230</commentid>
    <comment_count>3</comment_count>
    <who name="Fedora Update System">updates</who>
    <bug_when>2016-07-02 16:28:44 -0400</bug_when>
    <thetext>python-invoke-0.13.0-2.fc24 has been pushed to the Fedora 24 testing repository. If problems still persist, please make note of it in this bug report.
See https://fedoraproject.org/wiki/QA:Updates_Testing for
instructions on how to install test updates.
You can provide feedback for this update here: https://bodhi.fedoraproject.org/updates/FEDORA-2016-5bf9314019</thetext>
  </long_desc><long_desc isprivate="0" >
    <commentid>9479775</commentid>
    <comment_count>4</comment_count>
    <who name="Fedora Update System">updates</who>
    <bug_when>2016-07-05 00:54:30 -0400</bug_when>
    <thetext>python-invoke-0.13.0-2.fc24 has been pushed to the Fedora 24 stable repository. If problems still persist, please make note of it in this bug report.</thetext>
  </long_desc>
      
          <attachment
              isobsolete="0"
              ispatch="1"
              isprivate="0"
          >
            <attachid>1174837</attachid>
            <date>2016-07-01 04:13:00 -0400</date>
            <delta_ts>2016-07-01 04:13:00 -0400</delta_ts>
            <desc>Patch for invoke/monkey.py</desc>
            <filename>invoke-0.9.0-import-mswindows.patch</filename>
            <type>text/plain</type>
            <size>454</size>
            <attacher name="Emanuele Di Giacomo">emanuele.digiacomo</attacher>
            
              <data encoding="base64">LS0tIGludm9rZS9tb25rZXkucHkub3JpZwkyMDE2LTA3LTAxIDA5OjU0OjA2LjQ5NDA0MDkyMiAr
MDIwMAorKysgaW52b2tlL21vbmtleS5weQkyMDE2LTA3LTAxIDA5OjU2OjA1LjM2NzIzMzIwOSAr
MDIwMApAQCAtMSw3ICsxLDEyIEBACiAjIEZ1Y2tpbicgQS4KIAogaW1wb3J0IHNlbGVjdCwgZXJy
bm8sIG9zLCBzeXMKLWZyb20gc3VicHJvY2VzcyBpbXBvcnQgUG9wZW4gYXMgT3JpZ2luYWxQb3Bl
biwgbXN3aW5kb3dzLCBQSVBFCitmcm9tIHN1YnByb2Nlc3MgaW1wb3J0IFBvcGVuIGFzIE9yaWdp
bmFsUG9wZW4sIFBJUEUKK3RyeToKKyAgICBmcm9tIHN1YnByb2Nlc3MgaW1wb3J0IG1zd2luZG93
cworZXhjZXB0IEltcG9ydEVycm9yOgorICAgICMgcHl0aG9uID49IDMuNQorICAgIGZyb20gc3Vi
cHJvY2VzcyBpbXBvcnQgX21zd2luZG93cyBhcyBtc3dpbmRvd3MKIAogaW1wb3J0IHNpeAogCg==
</data>

          </attachment>
      

    </bug>

</bugzilla>