<?xml version="1.0" encoding="UTF-8" standalone="yes" ?>
<!DOCTYPE bugzilla SYSTEM "https://bugzilla.redhat.com/page.cgi?id=bugzilla.dtd">

<bugzilla version="4.4.12068.1" urlbase="https://bugzilla.redhat.com/" maintainer="bugzilla-error-list@redhat.com">

  <bug>
    <bug_id>1400249</bug_id>

    <creation_ts>2016-11-30 13:01:00 -0500</creation_ts>
    <short_desc>Wrong systemd unit in cloud-init</short_desc>
    <delta_ts>2017-03-23 14:21:47 -0400</delta_ts>
    <reporter_accessible>1</reporter_accessible>
    <cclist_accessible>1</cclist_accessible>
    <classification_id>2</classification_id>
    <classification>Fedora</classification>
    <product>Fedora</product>
    <component>cloud-init</component>
    <version>25</version>
    <rep_platform>Unspecified</rep_platform>
    <op_sys>Unspecified</op_sys>
    <bug_status>CLOSED</bug_status>
    <resolution>ERRATA</resolution>

    <bug_file_loc></bug_file_loc>
    <status_whiteboard></status_whiteboard>
    <keywords></keywords>
    <priority>unspecified</priority>
    <bug_severity>medium</bug_severity>
    <target_milestone>---</target_milestone>

    <everconfirmed>1</everconfirmed>
    <reporter name="Maxim Popov">max.popov</reporter>
    <assigned_to name="Garrett Holmstrom">gholms</assigned_to>
    <cc>adimania</cc>

    <cc>apevec</cc>

    <cc>bekzot.asimov</cc>

    <cc>gholms</cc>

    <cc>Jan.van.Eldik</cc>

    <cc>lars</cc>

    <cc>mattdm</cc>

    <cc>shardy</cc>

    <cc>s</cc>
    <qa_contact name="Fedora Extras Quality Assurance">extras-qa</qa_contact>

    <cf_fixed_in>cloud-init-0.7.9-4.fc26 cloud-init-0.7.8-6.fc25</cf_fixed_in>
  <cf_doc_type>If docs needed, set a value</cf_doc_type>
<cf_release_notes></cf_release_notes>
<cf_story_points>---</cf_story_points>

<cf_environment></cf_environment>
<cf_last_closed>2017-03-20 18:19:44</cf_last_closed>
<cf_type>Bug</cf_type>
<cf_regression_status>---</cf_regression_status>
<cf_mount_type>---</cf_mount_type>
<cf_documentation_action>---</cf_documentation_action>
<cf_crm></cf_crm>
<cf_verified_branch></cf_verified_branch>
<cf_category>---</cf_category>
<cf_ovirt_team>---</cf_ovirt_team>

<cf_cloudforms_team>---</cf_cloudforms_team>

<target_release>---</target_release>

<votes>0</votes>

<comment_sort_order>oldest_to_newest</comment_sort_order>
<long_desc isprivate="0">
<commentid>9944309</commentid>
<comment_count>0</comment_count>
<who name="Maxim Popov">max.popov</who>
<bug_when>2016-11-30 13:01:57 -0500</bug_when>
<thetext>Description of problem: /usr/lib/systemd/system/cloud-init.service contains references to &quot;networking.service&quot; unit. Because of that, the cloud-init service starts before the network is ready. Version-Release number of selected
component (if applicable): Version : 0.7.8 Release : 3.fc25 Fix: Replace &quot;networking.service&quot; with &quot;network.service&quot;.</thetext>
</long_desc>
<long_desc isprivate="0">
<commentid>9949087</commentid>
<comment_count>1</comment_count>
<who name="Lars Kellogg-Stedman">lars</who>
<bug_when>2016-12-01 16:51:29 -0500</bug_when>
<thetext>This won&apos;t work, at least not by itself. The &quot;network.service&quot; target is generated from the &quot;network&quot; sysv service in the initscripts package. This won&apos;t run on a system using NetworkManager. So, maybe a proper
fix would be to set dependencies both on network.service and NetworkManager.service.</thetext>
</long_desc>
<long_desc isprivate="0">
<commentid>9949626</commentid>
<comment_count>2</comment_count>
<who name="Lars Kellogg-Stedman">lars</who>
<bug_when>2016-12-01 21:43:22 -0500</bug_when>
<thetext>Also, as long as you&apos;re making changes to the systemd units, note that in 6565dcf (in fedora dist-git) someone added: Before=NetworkManager.target But they probably meant: Before=NetworkManager.service Because: # systemctl show
NetworkManager.target Unit NetworkManager.target could not be found.</thetext>
</long_desc>
<long_desc isprivate="0">
<commentid>10239736</commentid>
<comment_count>3</comment_count>
<who name="Fedora Update System">updates</who>
<bug_when>2017-03-14 19:32:00 -0400</bug_when>
<thetext>cloud-init-0.7.8-6.fc25 has been submitted as an update to Fedora 25. https://bodhi.fedoraproject.org/updates/FEDORA-2017-837115524e</thetext>
</long_desc>
<long_desc isprivate="0">
<commentid>10239753</commentid>
<comment_count>4</comment_count>
<who name="Fedora Update System">updates</who>
<bug_when>2017-03-14 19:35:12 -0400</bug_when>
<thetext>cloud-init-0.7.9-4.fc26 has been submitted as an update to Fedora 26. https://bodhi.fedoraproject.org/updates/FEDORA-2017-83671c0fa0</thetext>
</long_desc>
<long_desc isprivate="0">
<commentid>10240060</commentid>
<comment_count>5</comment_count>
<who name="Bekzot Azimov">bekzot.asimov</who>
<bug_when>2017-03-14 22:16:04 -0400</bug_when>
<thetext>*** Bug 1428492 has been marked as a duplicate of this bug. ***</thetext>
</long_desc>
<long_desc isprivate="0">
<commentid>10240211</commentid>
<comment_count>6</comment_count>
<who name="Bekzot Azimov">bekzot.asimov</who>
<bug_when>2017-03-14 23:54:14 -0400</bug_when>
<thetext>Tested with package: cloud-init-0.7.8-6.fc25 but failed again. Main error is &quot;[[0;1;31mFAILED[0m] Failed to start LSB: Bring up/down networking.&quot; ################## network.service error ######################### -- Reboot -- Mar
15 03:34:54 ip-172-20-78-113.build.gogoair.com systemd[1]: Starting LSB: Bring up/down networking... Mar 15 03:34:56 ip-172-20-78-113.build.gogoair.com systemd-sysctl[415]: Couldn&apos;t write &apos;0&apos; to
&apos;net/bridge/bridge-nf-call-iptables&apos;, ignoring: N Mar 15 03:34:56 ip-172-20-78-113.build.gogoair.com systemd-sysctl[415]: Couldn&apos;t write &apos;0&apos; to &apos;net/bridge/bridge-nf-call-ip6tables&apos;, ignoring: Mar 15 03:34:56
ip-172-20-78-113.build.gogoair.com systemd-sysctl[415]: Couldn&apos;t write &apos;0&apos; to &apos;net/bridge/bridge-nf-call-arptables&apos;, ignoring: Mar 15 03:34:57 ip-172-20-78-113.build.gogoair.com network[380]: Bringing up loopback interface: [
OK ] Mar 15 03:34:57 ip-172-20-78-113.build.gogoair.com network[380]: Bringing up interface eth0: ERROR : [/etc/sysconfig/network-scripts/ifup-e Mar 15 03:34:57 ip-172-20-78-113.build.gogoair.com /etc/sysconfig/network-scripts/ifup-eth[531]: Device
eth0 has different MAC address than exp Mar 15 03:34:57 ip-172-20-78-113.build.gogoair.com network[380]: [FAILED] Mar 15 03:34:57 ip-172-20-78-113.build.gogoair.com systemd-sysctl[548]: Couldn&apos;t write &apos;0&apos; to
&apos;net/bridge/bridge-nf-call-arptables&apos;, ignoring: Mar 15 03:34:57 ip-172-20-78-113.build.gogoair.com systemd-sysctl[548]: Couldn&apos;t write &apos;0&apos; to &apos;net/bridge/bridge-nf-call-iptables&apos;, ignoring: N Mar 15 03:34:57
ip-172-20-78-113.build.gogoair.com systemd-sysctl[548]: Couldn&apos;t write &apos;0&apos; to &apos;net/bridge/bridge-nf-call-ip6tables&apos;, ignoring: Mar 15 03:34:57 ip-172-20-78-113.build.gogoair.com systemd[1]: network.service: Control process
exited, code=exited status=1 Mar 15 03:34:57 ip-172-20-78-113.build.gogoair.com systemd[1]: Failed to start LSB: Bring up/down networking. Mar 15 03:34:57 ip-172-20-78-113.build.gogoair.com systemd[1]: network.service: Unit entered failed state. Mar
15 03:34:57 ip-172-20-78-113.build.gogoair.com systemd[1]: network.service: Failed with result &apos;exit-code&apos;. -- Reboot -- ################## cloud init logs ############################## [ 0.000000] Cannot get hvm parameter CONSOLE_EVTCHN
(18): -22! [ 0.443364] Cannot get hvm parameter CONSOLE_EVTCHN (18): -22! %G%G[[0;32m OK [0m] Stopped Journal Service. Starting Journal Service... [[0;32m OK [0m] Created slice system-sshd\x2dkeygen.slice. [[0;32m OK [0m] Set up automount Arbitrary
Executable File Formats File System Automount Point. [[0;32m OK [0m] Listening on udev Control Socket. [[0;32m OK [0m] Stopped target Switch Root. [[0;32m OK [0m] Created slice system-serial\x2dgetty.slice. Mounting Debug File System... Starting
Create list of required static device nodes for the current kernel... [[0;32m OK [0m] Created slice User and Session Slice. [[0;32m OK [0m] Reached target Slices. [[0;32m OK [0m] Reached target Swap. [[0;32m OK [0m] Created slice system-getty.slice.
Starting Apply Kernel Variables... [[0;32m OK [0m] Started Forward Password Requests to Wall Directory Watch. [[0;32m OK [0m] Reached target Paths. Mounting Huge Pages File System... Mounting POSIX Message Queue File System... [[0;32m OK [0m] Stopped
target Initrd File Systems. [[0;32m OK [0m] Reached target Encrypted Volumes. [[0;32m OK [0m] Listening on Process Core Dump Socket. [[0;32m OK [0m] Listening on /dev/initctl Compatibility Named Pipe. [[0;32m OK [0m] Reached target Remote File
Systems. [[0;32m OK [0m] Listening on udev Kernel Socket. Starting Remount Root and Kernel File Systems... [[0;32m OK [0m] Stopped target Initrd Root File System. [[0;32m OK [0m] Mounted Debug File System. [[0;32m OK [0m] Started Journal Service.
[[0;32m OK [0m] Mounted Huge Pages File System. [[0;32m OK [0m] Mounted POSIX Message Queue File System. [[0;32m OK [0m] Started Remount Root and Kernel File Systems. Starting Flush Journal to Persistent Storage... Starting udev Coldplug all
Devices... Starting Configure read-only root support... [[0;32m OK [0m] Started Create list of required static device nodes for the current kernel. Starting Create Static Device Nodes in /dev... [[0;32m OK [0m] Started udev Coldplug all Devices.
[[0;32m OK [0m] Started Apply Kernel Variables. [[0;32m OK [0m] Started Configure read-only root support. Starting Load/Save Random Seed... [[0;32m OK [0m] Started Load/Save Random Seed. [[0;32m OK [0m] Started Create Static Device Nodes in /dev.
Starting udev Kernel Device Manager... [[0;32m OK [0m] Reached target Local File Systems (Pre). [[0;32m OK [0m] Reached target Local File Systems. Starting Restore /run/initramfs on shutdown... Starting Initial cloud-init job (pre-networking)...
Starting Tell Plymouth To Write Out Runtime Data... [[0;32m OK [0m] Started Restore /run/initramfs on shutdown. [[0;32m OK [0m] Started Tell Plymouth To Write Out Runtime Data. [[0;32m OK [0m] Started udev Kernel Device Manager. [ 38.835955]
piix4_smbus 0000:00:01.3: SMBus base address uninitialized - upgrade BIOS or use force_addr=0xaddr [[0;32m OK [0m] Started Flush Journal to Persistent Storage. Starting Create Volatile Files and Directories... [[0;32m OK [0m] Started Create Volatile
Files and Directories. Starting Security Auditing Service... [[0;32m OK [0m] Found device /dev/ttyS0. %G%G[[0;32m OK [0m] Started Security Auditing Service. Starting Update UTMP about System Boot/Shutdown... [[0;32m OK [0m] Started Update UTMP about
System Boot/Shutdown. [[0;32m OK [0m] Reached target System Initialization. [[0;32m OK [0m] Listening on D-Bus System Message Bus Socket. [[0;32m OK [0m] Reached target Sockets. [[0;32m OK [0m] Started dnf makecache timer. [[0;32m OK [0m] Reached
target Basic System. [[0;32m OK [0m] Started Tailon Service. Starting System Logging Service... Starting LSB: Bring up/down networking... Starting Login Service... Starting NTP client/server... [[0;32m OK [0m] Started D-Bus System Message Bus.
[[0;32m OK [0m] Reached target sshd-keygen.target. [[0;32m OK [0m] Started Daily Cleanup of Temporary Directories. [[0;32m OK [0m] Started Updates mlocate database every day. [[0;32m OK [0m] Reached target Timers. [[0;32m OK [0m] Started System
Logging Service. [[0;32m OK [0m] Started NTP client/server. [[0;32m OK [0m] Started Login Service. [[0;1;31mFAILED[0m] Failed to start LSB: Bring up/down networking. See &apos;systemctl status network.service&apos; for details. [ 64.317647]
cloud-init[315]: Cloud-init v. 0.7.8 running &apos;init-local&apos; at Wed, 15 Mar 2017 03:35:14 +0000. Up 62.29 seconds. [[0;32m OK [0m] Started Initial cloud-init job (pre-networking). Starting Initial cloud-init job (metadata service crawler)...
[[0;32m OK [0m] Reached target Network (Pre). [ 65.080696] cloud-init[581]: Cloud-init v. 0.7.8 running &apos;init&apos; at Wed, 15 Mar 2017 03:35:16 +0000. Up 64.69 seconds. [ 65.080852] cloud-init[581]: ci-info: +++++++++++++++++++++++++++Net
device info++++++++++++++++++++++++++++ [ 65.080969] cloud-init[581]: ci-info: +--------+-------+-----------+-----------+-------+-------------------+ [ 65.081093] cloud-init[581]: ci-info: | Device | Up | Address | Mask | Scope | Hw-Address | [
65.081201] cloud-init[581]: ci-info: +--------+-------+-----------+-----------+-------+-------------------+ [ 65.081300] cloud-init[581]: ci-info: | lo: | True | 127.0.0.1 | 255.0.0.0 | . | . | [ 65.081397] cloud-init[581]: ci-info: | lo: | True | .
| . | d | . | [ 65.081496] cloud-init[581]: ci-info: | eth0: | False | . | . | . | 12:3f:5d:3b:03:38 | [ 65.081596] cloud-init[581]: ci-info: +--------+-------+-----------+-----------+-------+-------------------+ [ 65.081697] cloud-init[581]:
2017-03-15 03:35:17,086 - url_helper.py[WARNING]: Calling &apos;http://169.254.169.254/2009-04-04/meta-data/instance-id&apos; failed [0/120s]: request error [HTTPConnectionPool(host=&apos;169.254.169.254&apos;, port=80): Max retries exceeded with
url: /2009-04-04/meta-data/instance-id (Caused by NewConnectionError(&apos;&lt;requests.packages.urllib3.connection.HTTPConnection object at 0x7fdf43d359e8&gt;: Failed to establish a new connection: [Errno 101] Network is unreachable&apos;,))] [
66.090316] cloud-init[581]: 2017-03-15 03:35:18,095 - url_helper.py[WARNING]: Calling &apos;http://169.254.169.254/2009-04-04/meta-data/instance-id&apos; failed [1/120s]: request error [HTTPConnectionPool(host=&apos;169.254.169.254&apos;, port=80):
Max retries exceeded with url: /2009-04-04/meta-data/instance-id (Caused by NewConnectionError(&apos;&lt;requests.packages.urllib3.connection.HTTPConnection object at 0x7fdf43cd12b0&gt;: Failed to establish a new connection: [Errno 101] Network is
unreachable&apos;,))] [ 67.094006] cloud-init[581]: 2017-03-15 03:35:19,099 - url_helper.py[WARNING]: Calling &apos;http://169.254.169.254/2009-04-04/meta-data/instance-id&apos; failed [2/120s]: request error
[HTTPConnectionPool(host=&apos;169.254.169.254&apos;, port=80): Max retries exceeded with url: /2009-04-04/meta-data/instance-id (Caused by NewConnectionError(&apos;&lt;requests.packages.urllib3.connection.HTTPConnection object at 0x7fdf43cd10b8&gt;:
Failed to establish a new connection: [Errno 101] Network is unreachable&apos;,))] [ 68.097807] cloud-init[581]: 2017-03-15 03:35:20,103 - url_helper.py[WARNING]: Calling &apos;http://169.254.169.254/2009-04-04/meta-data/instance-id&apos; failed
[3/120s]: request error [HTTPConnectionPool(host=&apos;169.254.169.254&apos;, port=80): Max retries exceeded with url: /2009-04-04/meta-data/instance-id (Caused by NewConnectionError(&apos;&lt;requests.packages.urllib3.connection.HTTPConnection
object at 0x7fdf43cd1a58&gt;: Failed to establish a new connection: [Errno 101] Network is unreachable&apos;,))] [ 69.101689] cloud-init[581]: 2017-03-15 03:35:21,106 - url_helper.py[WARNING]: Calling
&apos;http://169.254.169.254/2009-04-04/meta-data/instance-id&apos; failed [4/120s]: request error [HTTPConnectionPool(host=&apos;169.254.169.254&apos;, port=80): Max retries exceeded with url: /2009-04-04/meta-data/instance-id (Caused by
NewConnectionError(&apos;&lt;requests.packages.urllib3.connection.HTTPConnection object at 0x7fdf43cd92b0&gt;: Failed to establish a new connection: [Errno 101] Network is unreachable&apos;,))] [ 70.105507] cloud-init[581]: 2017-03-15 03:35:22,110 -
url_helper.py[WARNING]: Calling &apos;http://169.254.169.254/2009-04-04/meta-data/instance-id&apos; failed [5/120s]: request error [HTTPConnectionPool(host=&apos;169.254.169.254&apos;, port=80): Max retries exceeded with url:
/2009-04-04/meta-data/instance-id (Caused by NewConnectionError(&apos;&lt;requests.packages.urllib3.connection.HTTPConnection object at 0x7fdf43cd9ac8&gt;: Failed to establish a new connection: [Errno 101] Network is unreachable&apos;,))] [
72.110567] cloud-init[581]: 2017-03-15 03:35:24,115 - url_helper.py[WARNING]: Calling &apos;http://169.254.169.254/2009-04-04/meta-data/instance-id&apos; failed [7/120s]: request error [HTTPConnectionPool(host=&apos;169.254.169.254&apos;, port=80):
Max retries exceeded with url: /2009-04-04/meta-data/instance-id (Caused by NewConnectionError(&apos;&lt;requests.packages.urllib3.connection.HTTPConnection object at 0x7fdf43cd90b8&gt;: Failed to establish a new connection: [Errno 101] Network is
unreachable&apos;,))] [ 74.115395] cloud-init[581]: 2017-03-15 03:35:26,120 - url_helper.py[WARNING]: Calling &apos;http://169.254.169.254/2009-04-04/meta-data/instance-id&apos; failed [9/120s]: request error
[HTTPConnectionPool(host=&apos;169.254.169.254&apos;, port=80): Max retries exceeded with url: /2009-04-04/meta-data/instance-id (Caused by NewConnectionError(&apos;&lt;requests.packages.urllib3.connection.HTTPConnection object at 0x7fdf43d355c0&gt;:
Failed to establish a new connection: [Errno 101] Network is unreachable&apos;,))] [ 76.120122] cloud-init[581]: 2017-03-15 03:35:28,125 - url_helper.py[WARNING]: Calling &apos;http://169.254.169.254/2009-04-04/meta-data/instance-id&apos; failed
[11/120s]: request error [HTTPConnectionPool(host=&apos;169.254.169.254&apos;, port=80): Max retries exceeded with url: /2009-04-04/meta-data/instance-id (Caused by NewConnectionError(&apos;&lt;requests.packages.urllib3.connection.HTTPConnection
object at 0x7fdf43cd1860&gt;: Failed to establish a new connection: [Errno 101] Network is unreachable&apos;,))] [ 78.124813] cloud-init[581]: 2017-03-15 03:35:30,130 - url_helper.py[WARNING]: Calling
&apos;http://169.254.169.254/2009-04-04/meta-data/instance-id&apos; failed [13/120s]: request error [HTTPConnectionPool(host=&apos;169.254.169.254&apos;, port=80): Max retries exceeded with url: /2009-04-04/meta-data/instance-id (Caused by
NewConnectionError(&apos;&lt;requests.packages.urllib3.connection.HTTPConnection object at 0x7fdf43cd1710&gt;: Failed to establish a new connection: [Errno 101] Network is unreachable&apos;,))] [ 80.129633] cloud-init[581]: 2017-03-15 03:35:32,134 -
url_helper.py[WARNING]: Calling &apos;http://169.254.169.254/2009-04-04/meta-data/instance-id&apos; failed [15/120s]: request error [HTTPConnectionPool(host=&apos;169.254.169.254&apos;, port=80): Max retries exceeded with url:
/2009-04-04/meta-data/instance-id (Caused by NewConnectionError(&apos;&lt;requests.packages.urllib3.connection.HTTPConnection object at 0x7fdf43ce2320&gt;: Failed to establish a new connection: [Errno 101] Network is unreachable&apos;,))] [
83.135790] cloud-init[581]: 2017-03-15 03:35:35,140 - url_helper.py[WARNING]: Calling &apos;http://169.254.169.254/2009-04-04/meta-data/instance-id&apos; failed [18/120s]: request error [HTTPConnectionPool(host=&apos;169.254.169.254&apos;, port=80):
Max retries exceeded with url: /2009-04-04/meta-data/instance-id (Caused by NewConnectionError(&apos;&lt;requests.packages.urllib3.connection.HTTPConnection object at 0x7fdf43d18f28&gt;: Failed to establish a new connection: [Errno 101] Network is
unreachable&apos;,))] [ 86.141492] cloud-init[581]: 2017-03-15 03:35:38,146 - url_helper.py[WARNING]: Calling &apos;http://169.254.169.254/2009-04-04/meta-data/instance-id&apos; failed [21/120s]: request error
[HTTPConnectionPool(host=&apos;169.254.169.254&apos;, port=80): Max retries exceeded with url: /2009-04-04/meta-data/instance-id (Caused by NewConnectionError(&apos;&lt;requests.packages.urllib3.connection.HTTPConnection object at 0x7fdf43cd1c50&gt;:
Failed to establish a new connection: [Errno 101] Network is unreachable&apos;,))] [ 89.147279] cloud-init[581]: 2017-03-15 03:35:41,152 - url_helper.py[WARNING]: Calling &apos;http://169.254.169.254/2009-04-04/meta-data/instance-id&apos; failed
[24/120s]: request error [HTTPConnectionPool(host=&apos;169.254.169.254&apos;, port=80): Max retries exceeded with url: /2009-04-04/meta-data/instance-id (Caused by NewConnectionError(&apos;&lt;requests.packages.urllib3.connection.HTTPConnection
object at 0x7fdf43cd90f0&gt;: Failed to establish a new connection: [Errno 101] Network is unreachable&apos;,))] [ 92.153087] cloud-init[581]: 2017-03-15 03:35:44,158 - url_helper.py[WARNING]: Calling
&apos;http://169.254.169.254/2009-04-04/meta-data/instance-id&apos; failed [27/120s]: request error [HTTPConnectionPool(host=&apos;169.254.169.254&apos;, port=80): Max retries exceeded with url: /2009-04-04/meta-data/instance-id (Caused by
NewConnectionError(&apos;&lt;requests.packages.urllib3.connection.HTTPConnection object at 0x7fdf43d359e8&gt;: Failed to establish a new connection: [Errno 101] Network is unreachable&apos;,))] [ 95.158922] cloud-init[581]: 2017-03-15 03:35:47,164 -
url_helper.py[WARNING]: Calling &apos;http://169.254.169.254/2009-04-04/meta-data/instance-id&apos; failed [30/120s]: request error [HTTPConnectionPool(host=&apos;169.254.169.254&apos;, port=80): Max retries exceeded with url:
/2009-04-04/meta-data/instance-id (Caused by NewConnectionError(&apos;&lt;requests.packages.urllib3.connection.HTTPConnection object at 0x7fdf43ce2b38&gt;: Failed to establish a new connection: [Errno 101] Network is unreachable&apos;,))] [
99.165902] cloud-init[581]: 2017-03-15 03:35:51,171 - url_helper.py[WARNING]: Calling &apos;http://169.254.169.254/2009-04-04/meta-data/instance-id&apos; failed [34/120s]: request error [HTTPConnectionPool(host=&apos;169.254.169.254&apos;, port=80):
Max retries exceeded with url: /2009-04-04/meta-data/instance-id (Caused by NewConnectionError(&apos;&lt;requests.packages.urllib3.connection.HTTPConnection object at 0x7fdf43ce2358&gt;: Failed to establish a new connection: [Errno 101] Network is
unreachable&apos;,))] [ 103.172680] cloud-init[581]: 2017-03-15 03:35:55,177 - url_helper.py[WARNING]: Calling &apos;http://169.254.169.254/2009-04-04/meta-data/instance-id&apos; failed [38/120s]: request error
[HTTPConnectionPool(host=&apos;169.254.169.254&apos;, port=80): Max retries exceeded with url: /2009-04-04/meta-data/instance-id (Caused by NewConnectionError(&apos;&lt;requests.packages.urllib3.connection.HTTPConnection object at 0x7fdf43cd9b00&gt;:
Failed to establish a new connection: [Errno 101] Network is unreachable&apos;,))] [ 107.179507] cloud-init[581]: 2017-03-15 03:35:59,184 - url_helper.py[WARNING]: Calling &apos;http://169.254.169.254/2009-04-04/meta-data/instance-id&apos; failed
[42/120s]: request error [HTTPConnectionPool(host=&apos;169.254.169.254&apos;, port=80): Max retries exceeded with url: /2009-04-04/meta-data/instance-id (Caused by NewConnectionError(&apos;&lt;requests.packages.urllib3.connection.HTTPConnection
object at 0x7fdf43d18d68&gt;: Failed to establish a new connection: [Errno 101] Network is unreachable&apos;,))] [ 111.186284] cloud-init[581]: 2017-03-15 03:36:03,191 - url_helper.py[WARNING]: Calling
&apos;http://169.254.169.254/2009-04-04/meta-data/instance-id&apos; failed [46/120s]: request error [HTTPConnectionPool(host=&apos;169.254.169.254&apos;, port=80): Max retries exceeded with url: /2009-04-04/meta-data/instance-id (Caused by
NewConnectionError(&apos;&lt;requests.packages.urllib3.connection.HTTPConnection object at 0x7fdf43cd1828&gt;: Failed to establish a new connection: [Errno 101] Network is unreachable&apos;,))] [ 115.193073] cloud-init[581]: 2017-03-15 03:36:07,198 -
url_helper.py[WARNING]: Calling &apos;http://169.254.169.254/2009-04-04/meta-data/instance-id&apos; failed [50/120s]: request error [HTTPConnectionPool(host=&apos;169.254.169.254&apos;, port=80): Max retries exceeded with url:
/2009-04-04/meta-data/instance-id (Caused by NewConnectionError(&apos;&lt;requests.packages.urllib3.connection.HTTPConnection object at 0x7fdf43ced390&gt;: Failed to establish a new connection: [Errno 101] Network is unreachable&apos;,))] [
120.201153] cloud-init[581]: 2017-03-15 03:36:12,206 - url_helper.py[WARNING]: Calling &apos;http://169.254.169.254/2009-04-04/meta-data/instance-id&apos; failed [55/120s]: request error [HTTPConnectionPool(host=&apos;169.254.169.254&apos;, port=80):
Max retries exceeded with url: /2009-04-04/meta-data/instance-id (Caused by NewConnectionError(&apos;&lt;requests.packages.urllib3.connection.HTTPConnection object at 0x7fdf43cd1048&gt;: Failed to establish a new connection: [Errno 101] Network is
unreachable&apos;,))] [ 125.209165] cloud-init[581]: 2017-03-15 03:36:17,214 - url_helper.py[WARNING]: Calling &apos;http://169.254.169.254/2009-04-04/meta-data/instance-id&apos; failed [60/120s]: request error
[HTTPConnectionPool(host=&apos;169.254.169.254&apos;, port=80): Max retries exceeded with url: /2009-04-04/meta-data/instance-id (Caused by NewConnectionError(&apos;&lt;requests.packages.urllib3.connection.HTTPConnection object at 0x7fdf43cd1f28&gt;:
Failed to establish a new connection: [Errno 101] Network is unreachable&apos;,))] [ 130.216594] cloud-init[581]: 2017-03-15 03:36:22,221 - url_helper.py[WARNING]: Calling &apos;http://169.254.169.254/2009-04-04/meta-data/instance-id&apos; failed
[65/120s]: request error [HTTPConnectionPool(host=&apos;169.254.169.254&apos;, port=80): Max retries exceeded with url: /2009-04-04/meta-data/instance-id (Caused by NewConnectionError(&apos;&lt;requests.packages.urllib3.connection.HTTPConnection
object at 0x7fdf43ce2780&gt;: Failed to establish a new connection: [Errno 101] Network is unreachable&apos;,))] [ 135.224454] cloud-init[581]: 2017-03-15 03:36:27,229 - url_helper.py[WARNING]: Calling
&apos;http://169.254.169.254/2009-04-04/meta-data/instance-id&apos; failed [70/120s]: request error [HTTPConnectionPool(host=&apos;169.254.169.254&apos;, port=80): Max retries exceeded with url: /2009-04-04/meta-data/instance-id (Caused by
NewConnectionError(&apos;&lt;requests.packages.urllib3.connection.HTTPConnection object at 0x7fdf43cd9240&gt;: Failed to establish a new connection: [Errno 101] Network is unreachable&apos;,))] [ 140.232378] cloud-init[581]: 2017-03-15 03:36:32,237 -
url_helper.py[WARNING]: Calling &apos;http://169.254.169.254/2009-04-04/meta-data/instance-id&apos; failed [75/120s]: request error [HTTPConnectionPool(host=&apos;169.254.169.254&apos;, port=80): Max retries exceeded with url:
/2009-04-04/meta-data/instance-id (Caused by NewConnectionError(&apos;&lt;requests.packages.urllib3.connection.HTTPConnection object at 0x7fdf43cedba8&gt;: Failed to establish a new connection: [Errno 101] Network is unreachable&apos;,))] [
146.241463] cloud-init[581]: 2017-03-15 03:36:38,246 - url_helper.py[WARNING]: Calling &apos;http://169.254.169.254/2009-04-04/meta-data/instance-id&apos; failed [81/120s]: request error [HTTPConnectionPool(host=&apos;169.254.169.254&apos;, port=80):
Max retries exceeded with url: /2009-04-04/meta-data/instance-id (Caused by NewConnectionError(&apos;&lt;requests.packages.urllib3.connection.HTTPConnection object at 0x7fdf43ceda20&gt;: Failed to establish a new connection: [Errno 101] Network is
unreachable&apos;,))] [ 152.250246] cloud-init[581]: 2017-03-15 03:36:44,255 - url_helper.py[WARNING]: Calling &apos;http://169.254.169.254/2009-04-04/meta-data/instance-id&apos; failed [87/120s]: request error
[HTTPConnectionPool(host=&apos;169.254.169.254&apos;, port=80): Max retries exceeded with url: /2009-04-04/meta-data/instance-id (Caused by NewConnectionError(&apos;&lt;requests.packages.urllib3.connection.HTTPConnection object at 0x7fdf43cd9128&gt;:
Failed to establish a new connection: [Errno 101] Network is unreachable&apos;,))] [ 158.258992] cloud-init[581]: 2017-03-15 03:36:50,264 - url_helper.py[WARNING]: Calling &apos;http://169.254.169.254/2009-04-04/meta-data/instance-id&apos; failed
[93/120s]: request error [HTTPConnectionPool(host=&apos;169.254.169.254&apos;, port=80): Max retries exceeded with url: /2009-04-04/meta-data/instance-id (Caused by NewConnectionError(&apos;&lt;requests.packages.urllib3.connection.HTTPConnection
object at 0x7fdf43ce2ba8&gt;: Failed to establish a new connection: [Errno 101] Network is unreachable&apos;,))] [ 164.267806] cloud-init[581]: 2017-03-15 03:36:56,272 - url_helper.py[WARNING]: Calling
&apos;http://169.254.169.254/2009-04-04/meta-data/instance-id&apos; failed [99/120s]: request error [HTTPConnectionPool(host=&apos;169.254.169.254&apos;, port=80): Max retries exceeded with url: /2009-04-04/meta-data/instance-id (Caused by
NewConnectionError(&apos;&lt;requests.packages.urllib3.connection.HTTPConnection object at 0x7fdf43cd1b00&gt;: Failed to establish a new connection: [Errno 101] Network is unreachable&apos;,))] [ 170.276691] cloud-init[581]: 2017-03-15 03:37:02,281 -
url_helper.py[WARNING]: Calling &apos;http://169.254.169.254/2009-04-04/meta-data/instance-id&apos; failed [105/120s]: request error [HTTPConnectionPool(host=&apos;169.254.169.254&apos;, port=80): Max retries exceeded with url:
/2009-04-04/meta-data/instance-id (Caused by NewConnectionError(&apos;&lt;requests.packages.urllib3.connection.HTTPConnection object at 0x7fdf43cf4400&gt;: Failed to establish a new connection: [Errno 101] Network is unreachable&apos;,))] [
177.287714] cloud-init[581]: 2017-03-15 03:37:09,293 - url_helper.py[WARNING]: Calling &apos;http://169.254.169.254/2009-04-04/meta-data/instance-id&apos; failed [112/120s]: request error [HTTPConnectionPool(host=&apos;169.254.169.254&apos;,
port=80): Max retries exceeded with url: /2009-04-04/meta-data/instance-id (Caused by NewConnectionError(&apos;&lt;requests.packages.urllib3.connection.HTTPConnection object at 0x7fdf43ced438&gt;: Failed to establish a new connection: [Errno 101]
Network is unreachable&apos;,))] [ 184.314250] cloud-init[581]: 2017-03-15 03:37:16,319 - url_helper.py[WARNING]: Calling &apos;http://169.254.169.254/2009-04-04/meta-data/instance-id&apos; failed [119/120s]: request error
[HTTPConnectionPool(host=&apos;169.254.169.254&apos;, port=80): Max retries exceeded with url: /2009-04-04/meta-data/instance-id (Caused by NewConnectionError(&apos;&lt;requests.packages.urllib3.connection.HTTPConnection object at 0x7fdf43ced860&gt;:
Failed to establish a new connection: [Errno 101] Network is unreachable&apos;,))] [ 191.323451] cloud-init[581]: 2017-03-15 03:37:23,327 - DataSourceEc2.py[CRITICAL]: Giving up on md from
[&apos;http://169.254.169.254/2009-04-04/meta-data/instance-id&apos;] after 126 seconds</thetext>
</long_desc>
<long_desc isprivate="0">
<commentid>10240323</commentid>
<comment_count>7</comment_count>
<who name="Fedora Update System">updates</who>
<bug_when>2017-03-15 00:24:45 -0400</bug_when>
<thetext>cloud-init-0.7.9-4.fc26 has been pushed to the Fedora 26 testing repository. If problems still persist, please make note of it in this bug report. See https://fedoraproject.org/wiki/QA:Updates_Testing for instructions on how to install test
updates. You can provide feedback for this update here: https://bodhi.fedoraproject.org/updates/FEDORA-2017-83671c0fa0</thetext>
</long_desc>
<long_desc isprivate="0">
<commentid>10240356</commentid>
<comment_count>8</comment_count>
<who name="Bekzot Azimov">bekzot.asimov</who>
<bug_when>2017-03-15 00:59:41 -0400</bug_when>
<thetext>Please ignore comment 6. Fedora 25 at bake stage is creating another HWADDR, we are adding another cleanup of HWADDR at the end of bake step to fix that. fedora 24 usually did not do that.</thetext>
</long_desc>
<long_desc isprivate="0">
<commentid>10243385</commentid>
<comment_count>9</comment_count>
<who name="Fedora Update System">updates</who>
<bug_when>2017-03-15 15:58:28 -0400</bug_when>
<thetext>cloud-init-0.7.8-6.fc25 has been pushed to the Fedora 25 testing repository. If problems still persist, please make note of it in this bug report. See https://fedoraproject.org/wiki/QA:Updates_Testing for instructions on how to install test
updates. You can provide feedback for this update here: https://bodhi.fedoraproject.org/updates/FEDORA-2017-837115524e</thetext>
</long_desc>
<long_desc isprivate="0">
<commentid>10256088</commentid>
<comment_count>10</comment_count>
<who name="Fedora Update System">updates</who>
<bug_when>2017-03-20 18:19:44 -0400</bug_when>
<thetext>cloud-init-0.7.9-4.fc26 has been pushed to the Fedora 26 stable repository. If problems still persist, please make note of it in this bug report.</thetext>
</long_desc>
<long_desc isprivate="0">
<commentid>10271151</commentid>
<comment_count>11</comment_count>
<who name="Fedora Update System">updates</who>
<bug_when>2017-03-23 14:21:47 -0400</bug_when>
<thetext>cloud-init-0.7.8-6.fc25 has been pushed to the Fedora 25 stable repository. If problems still persist, please make note of it in this bug report.</thetext>
</long_desc>

</bug>

</bugzilla>
