<?xml version="1.0" encoding="UTF-8" standalone="yes" ?>
<!DOCTYPE bugzilla SYSTEM "https://bugzilla.redhat.com/page.cgi?id=bugzilla.dtd">

<bugzilla version="4.4.12068.1"
          urlbase="https://bugzilla.redhat.com/"
          
          maintainer="bugzilla-error-list@redhat.com"
>

    <bug>
          <bug_id>1278201</bug_id>
          
          <creation_ts>2015-11-04 17:39:00 -0500</creation_ts>
          <short_desc>ImportError: No module named &apos;pygtk&apos;</short_desc>
          <delta_ts>2016-12-12 00:16:19 -0500</delta_ts>
          <reporter_accessible>1</reporter_accessible>
          <cclist_accessible>1</cclist_accessible>
          <classification_id>2</classification_id>
          <classification>Fedora</classification>
          <product>Fedora</product>
          <component>fonttools</component>
          <version>25</version>
          <rep_platform>Unspecified</rep_platform>
          <op_sys>Unspecified</op_sys>
          <bug_status>CLOSED</bug_status>
          <resolution>NEXTRELEASE</resolution>
          
          
          <bug_file_loc></bug_file_loc>
          <status_whiteboard></status_whiteboard>
          <keywords></keywords>
          <priority>unspecified</priority>
          <bug_severity>unspecified</bug_severity>
          <target_milestone>---</target_milestone>
          
          
          <everconfirmed>1</everconfirmed>
          <reporter name="Hin-Tak Leung">htl10</reporter>
          <assigned_to name="Parag Nemade">pnemade</assigned_to>
          <cc>fonts-bugs</cc>
    
    
    <cc>pnemade</cc>
          <qa_contact name="Fedora Extras Quality Assurance">extras-qa</qa_contact>
          
          <cf_fixed_in></cf_fixed_in>
          <cf_doc_type>Bug Fix</cf_doc_type>
          <cf_release_notes></cf_release_notes>
          <cf_story_points>---</cf_story_points>
          
          <cf_environment></cf_environment>
          <cf_last_closed>2016-12-12 00:16:19</cf_last_closed>
          <cf_type>Bug</cf_type>
          <cf_regression_status>---</cf_regression_status>
          <cf_mount_type>---</cf_mount_type>
          <cf_documentation_action>---</cf_documentation_action>
          <cf_crm></cf_crm>
          <cf_verified_branch></cf_verified_branch>
          <cf_category>---</cf_category>
          <cf_ovirt_team>---</cf_ovirt_team>
          
          <cf_cloudforms_team>---</cf_cloudforms_team>
          
          
          
          
          <target_release>---</target_release>
          
          <votes>0</votes>

      

      

      

          <comment_sort_order>oldest_to_newest</comment_sort_order>  
          <long_desc isprivate="0" >
    <commentid>8793116</commentid>
    <comment_count>0</comment_count>
    <who name="Hin-Tak Leung">htl10</who>
    <bug_when>2015-11-04 17:39:04 -0500</bug_when>
    <thetext>Description of problem:

# pyftinspect --help
Traceback (most recent call last):
  File &quot;/usr/bin/pyftinspect&quot;, line 9, in &lt;module&gt;
    load_entry_point(&apos;fonttools==3.0&apos;, &apos;console_scripts&apos;, &apos;pyftinspect&apos;)()
  File &quot;/usr/lib/python3.4/site-packages/pkg_resources/__init__.py&quot;, line 558, in load_entry_point
    return get_distribution(dist).load_entry_point(group, name)
  File &quot;/usr/lib/python3.4/site-packages/pkg_resources/__init__.py&quot;, line 2682, in load_entry_point
    return ep.load()
  File &quot;/usr/lib/python3.4/site-packages/pkg_resources/__init__.py&quot;, line 2355, in load
    return self.resolve()
  File &quot;/usr/lib/python3.4/site-packages/pkg_resources/__init__.py&quot;, line 2361, in resolve
    module = __import__(self.module_name, fromlist=[&apos;__name__&apos;], level=0)
  File &quot;/usr/lib/python3.4/site-packages/FontTools/fontTools/inspect.py&quot;, line 11, in &lt;module&gt;
    import pygtk
ImportError: No module named &apos;pygtk&apos;


# locate pygtk.py 
/usr/lib64/python2.7/site-packages/pygtk.py
/usr/lib64/python2.7/site-packages/pygtk.pyc
/usr/lib64/python2.7/site-packages/pygtk.pyo


Version-Release number of selected component (if applicable):
fonttools-3.0-1.fc23
pygobject2-2.28.6-14.fc23.x86_64
python3-gobject-base-3.18.0-2.fc23.x86_64


How reproducible:
always

Steps to Reproduce:
1. pyftinspect --help
2.
3.

Actual results:
as above

Expected results:
Anything else except the above.

Additional info:

It looks like fonttools-3.0-1.fc23 depends on python3 but pygobject2-2.28.6-14.fc23.x86_64 is python2, and I could not find equivalent python3 module. In any case, dependency should be automatic.</thetext>
  </long_desc><long_desc isprivate="0" >
    <commentid>9922346</commentid>
    <comment_count>1</comment_count>
    <who name="Fedora End Of Life">jkurik</who>
    <bug_when>2016-11-24 08:05:21 -0500</bug_when>
    <thetext>This message is a reminder that Fedora 23 is nearing its end of life.
Approximately 4 (four) weeks from now Fedora will stop maintaining
and issuing updates for Fedora 23. It is Fedora&apos;s policy to close all
bug reports from releases that are no longer maintained. At that time
this bug will be closed as EOL if it remains open with a Fedora  &apos;version&apos;
of &apos;23&apos;.

Package Maintainer: If you wish for this bug to remain open because you
plan to fix it in a currently maintained version, simply change the &apos;version&apos; 
to a later Fedora version.

Thank you for reporting this issue and we are sorry that we were not 
able to fix it before Fedora 23 is end of life. If you would still like 
to see this bug fixed and are able to reproduce it against a later version 
of Fedora, you are encouraged  change the &apos;version&apos; to a later Fedora 
version prior this bug is closed as described in the policy above.

Although we aim to fix as many bugs as possible during every release&apos;s 
lifetime, sometimes those efforts are overtaken by events. Often a 
more recent Fedora release includes newer upstream software that fixes 
bugs or makes them obsolete.</thetext>
  </long_desc><long_desc isprivate="0" >
    <commentid>9926325</commentid>
    <comment_count>2</comment_count>
    <who name="Hin-Tak Leung">htl10</who>
    <bug_when>2016-11-24 15:38:27 -0500</bug_when>
    <thetext>Still a problem with f24 - just re-testing before I upgrade to f25.</thetext>
  </long_desc><long_desc isprivate="0" >
    <commentid>9929912</commentid>
    <comment_count>3</comment_count>
    <who name="Hin-Tak Leung">htl10</who>
    <bug_when>2016-11-25 08:14:47 -0500</bug_when>
    <thetext>[root@localhost ~]# pyftinspect --help
Traceback (most recent call last):
  File &quot;/usr/bin/pyftinspect&quot;, line 9, in &lt;module&gt;
    load_entry_point(&apos;fonttools==3.0&apos;, &apos;console_scripts&apos;, &apos;pyftinspect&apos;)()
  File &quot;/usr/lib/python3.5/site-packages/pkg_resources/__init__.py&quot;, line 542, in load_entry_point
    return get_distribution(dist).load_entry_point(group, name)
  File &quot;/usr/lib/python3.5/site-packages/pkg_resources/__init__.py&quot;, line 2575, in load_entry_point
    return ep.load()
  File &quot;/usr/lib/python3.5/site-packages/pkg_resources/__init__.py&quot;, line 2235, in load
    return self.resolve()
  File &quot;/usr/lib/python3.5/site-packages/pkg_resources/__init__.py&quot;, line 2241, in resolve
    module = __import__(self.module_name, fromlist=[&apos;__name__&apos;], level=0)
  File &quot;/usr/lib/python3.5/site-packages/FontTools/fontTools/inspect.py&quot;, line 11, in &lt;module&gt;
    import pygtk
ImportError: No module named &apos;pygtk&apos;
[root@localhost ~]# rpm -qf /usr/bin/pyftinspect
fonttools-3.0-5.fc25.noarch</thetext>
  </long_desc><long_desc isprivate="0" >
    <commentid>9975367</commentid>
    <comment_count>4</comment_count>
    <who name="Parag Nemade">pnemade</who>
    <bug_when>2016-12-12 00:16:19 -0500</bug_when>
    <thetext>This is fixed now in fonttools-3.2.2-2 build for f24+ releases.</thetext>
  </long_desc>
      
      

    </bug>

</bugzilla>