<?xml version="1.0" encoding="UTF-8" standalone="yes" ?>
<!DOCTYPE bugzilla SYSTEM "https://bugzilla.redhat.com/page.cgi?id=bugzilla.dtd">

<bugzilla version="4.4.12068.1"
          urlbase="https://bugzilla.redhat.com/"
          
          maintainer="bugzilla-error-list@redhat.com"
>

    <bug>
          <bug_id>1381538</bug_id>
          
          <creation_ts>2016-10-04 08:04:00 -0400</creation_ts>
          <short_desc>NameError: global name &apos;AnsibleError&apos; is not defined</short_desc>
          <delta_ts>2016-11-19 16:12:26 -0500</delta_ts>
          <reporter_accessible>1</reporter_accessible>
          <cclist_accessible>1</cclist_accessible>
          <classification_id>2</classification_id>
          <classification>Fedora</classification>
          <product>Fedora</product>
          <component>ansible</component>
          <version>25</version>
          <rep_platform>x86_64</rep_platform>
          <op_sys>Linux</op_sys>
          <bug_status>CLOSED</bug_status>
          <resolution>ERRATA</resolution>
          
          
          <bug_file_loc></bug_file_loc>
          <status_whiteboard></status_whiteboard>
          <keywords></keywords>
          <priority>unspecified</priority>
          <bug_severity>unspecified</bug_severity>
          <target_milestone>---</target_milestone>
          
          
          <everconfirmed>1</everconfirmed>
          <reporter name="F.J. Simon">simon.sinx17</reporter>
          <assigned_to name="Kevin Fenzi">kevin</assigned_to>
          <cc>a.badger</cc>
    
    
    <cc>athmanem</cc>
    
    
    <cc>kevin</cc>
    
    
    <cc>kupo</cc>
    
    
    <cc>mark</cc>
    
    
    <cc>maxim</cc>
    
    
    <cc>simon.sinx17</cc>
    
    
    <cc>toromoti</cc>
          <qa_contact name="Fedora Extras Quality Assurance">extras-qa</qa_contact>
          
          <cf_fixed_in>ansible-2.2.0.0-3.fc24 ansible-2.2.0.0-3.fc25</cf_fixed_in>
          <cf_doc_type>If docs needed, set a value</cf_doc_type>
          <cf_release_notes></cf_release_notes>
          <cf_story_points>---</cf_story_points>
          
          <cf_environment></cf_environment>
          <cf_last_closed>2016-11-07 18:27:52</cf_last_closed>
          <cf_type>Bug</cf_type>
          <cf_regression_status>---</cf_regression_status>
          <cf_mount_type>---</cf_mount_type>
          <cf_documentation_action>---</cf_documentation_action>
          <cf_crm></cf_crm>
          <cf_verified_branch></cf_verified_branch>
          <cf_category>---</cf_category>
          <cf_ovirt_team>---</cf_ovirt_team>
          
          <cf_cloudforms_team>---</cf_cloudforms_team>
          <external_bugs name="Github">17895</external_bugs>
          
          
          
          <target_release>---</target_release>
          
          <votes>0</votes>

      

      

      

          <comment_sort_order>oldest_to_newest</comment_sort_order>  
          <long_desc isprivate="0" >
    <commentid>9764352</commentid>
    <comment_count>0</comment_count>
    <who name="F.J. Simon">simon.sinx17</who>
    <bug_when>2016-10-04 08:04:48 -0400</bug_when>
    <thetext>Description of problem:

typo in playbook resulted in unhandled exception

Version-Release number of selected component (if applicable):

ansible 2.1.2.0

How reproducible:

# site.yml
---

- hosts: all
  tasks:
    - include: test.yml

# test.yml
---
hosts: all

please note the missing &quot;-&quot; before hosts

cmd from dir where the files are located:
ansible-playbook site.yml

Actual results:

ansible-playbook site.yml -vvvv
Using /home/user/a-bug-project/ansible.cfg as config file
 [WARNING]: provided hosts list is empty, only localhost is available

ERROR! Unexpected Exception: global name &apos;AnsibleError&apos; is not defined
the full traceback was:

Traceback (most recent call last):
  File &quot;/usr/bin/ansible-playbook&quot;, line 92, in &lt;module&gt;
    exit_code = cli.run()
  File &quot;/usr/lib/python2.7/site-packages/ansible/cli/playbook.py&quot;, line 154, in run
    results = pbex.run()
  File &quot;/usr/lib/python2.7/site-packages/ansible/executor/playbook_executor.py&quot;, line 73, in run
    pb = Playbook.load(playbook_path, variable_manager=self._variable_manager, loader=self._loader)
  File &quot;/usr/lib/python2.7/site-packages/ansible/playbook/__init__.py&quot;, line 53, in load
    pb._load_playbook_data(file_name=file_name, variable_manager=variable_manager)
  File &quot;/usr/lib/python2.7/site-packages/ansible/playbook/__init__.py&quot;, line 98, in _load_playbook_data
    entry_obj = Play.load(entry, variable_manager=variable_manager, loader=self._loader)
  File &quot;/usr/lib/python2.7/site-packages/ansible/playbook/play.py&quot;, line 115, in load
    return p.load_data(data, variable_manager=variable_manager, loader=loader)
  File &quot;/usr/lib/python2.7/site-packages/ansible/playbook/base.py&quot;, line 219, in load_data
    self._attributes[name] = method(name, ds[name])
  File &quot;/usr/lib/python2.7/site-packages/ansible/playbook/play.py&quot;, line 145, in _load_tasks
    return load_list_of_blocks(ds=ds, play=self, variable_manager=self._variable_manager, loader=self._loader)
  File &quot;/usr/lib/python2.7/site-packages/ansible/playbook/helpers.py&quot;, line 58, in load_list_of_blocks
    loader=loader
  File &quot;/usr/lib/python2.7/site-packages/ansible/playbook/block.py&quot;, line 79, in load
    return b.load_data(data, variable_manager=variable_manager, loader=loader)
  File &quot;/usr/lib/python2.7/site-packages/ansible/playbook/base.py&quot;, line 219, in load_data
    self._attributes[name] = method(name, ds[name])
  File &quot;/usr/lib/python2.7/site-packages/ansible/playbook/block.py&quot;, line 115, in _load_block
    use_handlers=self._use_handlers,
  File &quot;/usr/lib/python2.7/site-packages/ansible/playbook/helpers.py&quot;, line 181, in load_list_of_tasks
    raise AnsibleError(&quot;included task files must contain a list of tasks&quot;, obj=data)
NameError: global name &apos;AnsibleError&apos; is not defined

Expected results:

error handling

Additional info:

none</thetext>
  </long_desc><long_desc isprivate="0" >
    <commentid>9765342</commentid>
    <comment_count>1</comment_count>
    <who name="Kevin Fenzi">kevin</who>
    <bug_when>2016-10-04 11:50:15 -0400</bug_when>
    <thetext>You have a external github link added, but it doesn&apos;t seem to load. Can you share the upstream issue on this again please?

I&apos;m not sure we want to carry any patches to this, but letting upstream know and fix it will get us the fix too, so thanks for filing. :)</thetext>
  </long_desc><long_desc isprivate="0" >
    <commentid>9765391</commentid>
    <comment_count>2</comment_count>
    <who name="F.J. Simon">simon.sinx17</who>
    <bug_when>2016-10-04 12:11:05 -0400</bug_when>
    <thetext>@Kevin Fenzi - the link requested :

https://github.com/ansible/ansible/issues/17895

As far as fix is concerned upstream is working hard :)</thetext>
  </long_desc><long_desc isprivate="0" >
    <commentid>9848185</commentid>
    <comment_count>3</comment_count>
    <who name="Fedora Update System">updates</who>
    <bug_when>2016-11-02 13:30:55 -0400</bug_when>
    <thetext>ansible-2.2.0.0-2.fc24 has been submitted as an update to Fedora 24. https://bodhi.fedoraproject.org/updates/FEDORA-2016-e348c4e0e3</thetext>
  </long_desc><long_desc isprivate="0" >
    <commentid>9848199</commentid>
    <comment_count>4</comment_count>
    <who name="Fedora Update System">updates</who>
    <bug_when>2016-11-02 13:31:40 -0400</bug_when>
    <thetext>ansible-2.2.0.0-2.fc25 has been submitted as an update to Fedora 25. https://bodhi.fedoraproject.org/updates/FEDORA-2016-a5f9956e38</thetext>
  </long_desc><long_desc isprivate="0" >
    <commentid>9863748</commentid>
    <comment_count>5</comment_count>
    <who name="Fedora Update System">updates</who>
    <bug_when>2016-11-04 23:33:13 -0400</bug_when>
    <thetext>ansible-2.2.0.0-2.fc24 has been pushed to the Fedora 24 testing repository. If problems still persist, please make note of it in this bug report.
See https://fedoraproject.org/wiki/QA:Updates_Testing for
instructions on how to install test updates.
You can provide feedback for this update here: https://bodhi.fedoraproject.org/updates/FEDORA-2016-e348c4e0e3</thetext>
  </long_desc><long_desc isprivate="0" >
    <commentid>9864070</commentid>
    <comment_count>6</comment_count>
    <who name="Fedora Update System">updates</who>
    <bug_when>2016-11-05 12:01:31 -0400</bug_when>
    <thetext>ansible-2.2.0.0-3.fc24 has been submitted as an update to Fedora 24. https://bodhi.fedoraproject.org/updates/FEDORA-2016-3113e71193</thetext>
  </long_desc><long_desc isprivate="0" >
    <commentid>9864077</commentid>
    <comment_count>7</comment_count>
    <who name="Fedora Update System">updates</who>
    <bug_when>2016-11-05 12:02:10 -0400</bug_when>
    <thetext>ansible-2.2.0.0-3.fc25 has been submitted as an update to Fedora 25. https://bodhi.fedoraproject.org/updates/FEDORA-2016-3ccb098630</thetext>
  </long_desc><long_desc isprivate="0" >
    <commentid>9864234</commentid>
    <comment_count>8</comment_count>
    <who name="Fedora Update System">updates</who>
    <bug_when>2016-11-05 15:01:25 -0400</bug_when>
    <thetext>ansible-2.2.0.0-3.fc25 has been pushed to the Fedora 25 testing repository. If problems still persist, please make note of it in this bug report.
See https://fedoraproject.org/wiki/QA:Updates_Testing for
instructions on how to install test updates.
You can provide feedback for this update here: https://bodhi.fedoraproject.org/updates/FEDORA-2016-3ccb098630</thetext>
  </long_desc><long_desc isprivate="0" >
    <commentid>9864471</commentid>
    <comment_count>9</comment_count>
    <who name="Fedora Update System">updates</who>
    <bug_when>2016-11-05 21:53:31 -0400</bug_when>
    <thetext>ansible-2.2.0.0-3.fc24 has been pushed to the Fedora 24 testing repository. If problems still persist, please make note of it in this bug report.
See https://fedoraproject.org/wiki/QA:Updates_Testing for
instructions on how to install test updates.
You can provide feedback for this update here: https://bodhi.fedoraproject.org/updates/FEDORA-2016-3113e71193</thetext>
  </long_desc><long_desc isprivate="0" >
    <commentid>9869311</commentid>
    <comment_count>10</comment_count>
    <who name="Fedora Update System">updates</who>
    <bug_when>2016-11-07 18:27:52 -0500</bug_when>
    <thetext>ansible-2.2.0.0-3.fc24 has been pushed to the Fedora 24 stable repository. If problems still persist, please make note of it in this bug report.</thetext>
  </long_desc><long_desc isprivate="0" >
    <commentid>9905840</commentid>
    <comment_count>11</comment_count>
    <who name="Fedora Update System">updates</who>
    <bug_when>2016-11-19 16:12:26 -0500</bug_when>
    <thetext>ansible-2.2.0.0-3.fc25 has been pushed to the Fedora 25 stable repository. If problems still persist, please make note of it in this bug report.</thetext>
  </long_desc>
      
      

    </bug>

</bugzilla>